<?xml version="1.0"?>
<!-- created with Phobos 0.7 -->
  <robot name="RH5">

    <link name="RH5_Root_Link">
      <inertial>
        <origin xyz="0 0.064 0.139" rpy="0 0 0"/>
        <mass value="3.341"/>
        <inertia ixx="0.001" ixy="0" ixz="0" iyy="0.001" iyz="0" izz="0.001"/>
      </inertial>
      <visual name="visual_0_RH5_Root_Link">
        <origin xyz="0 0 0" rpy="0 0 0"/>
        <geometry>
          <mesh filename="../meshes/stl/RH5_Root_Link.001.stl" scale="1.0 1.0 1.0"/>
        </geometry>
        <material name="WhitePlastic"/>
      </visual>
      <collision name="collision_RH5_Root_Link.001">
        <origin xyz="0.002 0.037 0.148" rpy="0 0 0"/>
        <geometry>
          <mesh filename="../meshes/stl/RH5_Root_Link.006.stl" scale="1.0 1.0 1.0"/>
        </geometry>
      </collision>
    </link>

    <link name="BodyBase_Link">
      <inertial>
        <origin xyz="0 -0.085 0.091" rpy="0 0 0"/>
        <mass value="1.463"/>
        <inertia ixx="0.007" ixy="0" ixz="0" iyy="0.007" iyz="0" izz="0.007"/>
      </inertial>
      <visual name="visual_0_Body_Act1_Link">
        <origin xyz="0.077 -0.092 -0.023" rpy="2.902 0.045 1.56"/>
        <geometry>
          <mesh filename="../meshes/stl/Body_Act1_Link.001.stl" scale="1.0 1.0 1.0"/>
        </geometry>
        <material name="Steel"/>
      </visual>
      <visual name="visual_0_Body_Act2_Link">
        <origin xyz="-0.077 -0.092 -0.023" rpy="-2.902 0.045 1.582"/>
        <geometry>
          <mesh filename="../meshes/stl/Body_Act2_Link.001.stl" scale="1.0 1.0 1.0"/>
        </geometry>
        <material name="Steel"/>
      </visual>
      <visual name="visual_0_Body_B11_Link">
        <origin xyz="0.02 -0.081 0.21" rpy="2.902 0 1.571"/>
        <geometry>
          <mesh filename="../meshes/stl/Body_B11_Link.001.stl" scale="1.0 1.0 1.0"/>
        </geometry>
        <material name="Steel"/>
      </visual>
      <visual name="visual_0_Body_B12_Link">
        <origin xyz="0.02 -0.081 0.21" rpy="2.902 0.045 1.56"/>
        <geometry>
          <mesh filename="../meshes/stl/Body_B12_Link.001.stl" scale="1.0 1.0 1.0"/>
        </geometry>
        <material name="Steel"/>
      </visual>
      <visual name="visual_0_Body_B21_Link">
        <origin xyz="-0.02 -0.08 0.21" rpy="-2.902 0 1.571"/>
        <geometry>
          <mesh filename="../meshes/stl/Body_B21_Link.001.stl" scale="1.0 1.0 1.0"/>
        </geometry>
        <material name="Steel"/>
      </visual>
      <visual name="visual_0_Body_B22_Link">
        <origin xyz="-0.02 -0.08 0.21" rpy="-2.902 0.045 1.582"/>
        <geometry>
          <mesh filename="../meshes/stl/Body_B22_Link.001.stl" scale="1.0 1.0 1.0"/>
        </geometry>
        <material name="Steel"/>
      </visual>
    </link>

    <link name="BodyPitch_Link">
      <inertial>
        <origin xyz="0 0 0" rpy="0 0 0"/>
        <mass value="0.085"/>
        <inertia ixx="0.001" ixy="0" ixz="0" iyy="0.001" iyz="0" izz="0.001"/>
      </inertial>
      <visual name="visual_0_BodyPitch_Link">
        <origin xyz="0 0 0" rpy="0 0 0"/>
        <geometry>
          <mesh filename="../meshes/stl/BodyPitch_Link.001.stl" scale="1.0 1.0 1.0"/>
        </geometry>
        <material name="Steel"/>
      </visual>
    </link>

    <link name="BodyRoll_Link">
      <inertial>
        <origin xyz="-0.018 0 0.026" rpy="0 0 0"/>
        <mass value="0.315"/>
        <inertia ixx="0.001" ixy="0" ixz="0" iyy="0.001" iyz="0" izz="0.001"/>
      </inertial>
      <visual name="visual_0_BodyRoll_Link">
        <origin xyz="0 0 0" rpy="0 0 0"/>
        <geometry>
          <mesh filename="../meshes/stl/BodyRoll_Link.001.stl" scale="1.0 1.0 1.0"/>
        </geometry>
        <material name="Steel"/>
      </visual>
    </link>

    <link name="BodyYaw_Link">
      <inertial>
        <origin xyz="-0.013 0 0.274" rpy="0 0 0"/>
        <mass value="24.861"/>
        <inertia ixx="0.004" ixy="-0.001" ixz="0" iyy="0.004" iyz="0" izz="0.004"/>
      </inertial>
      <visual name="ALvisual_0_Arm">
        <origin xyz="-0.048 0 -0.217" rpy="0 0 1.937"/>
        <geometry>
          <mesh filename="../meshes/stl/LeftArm.001.stl" scale="1.0 1.0 1.0"/>
        </geometry>
        <material name="Steel"/>
      </visual>
      <visual name="visual_0_BodyYaw_Act1_Link">
        <origin xyz="-0.145 0 0.047" rpy="0 0 0"/>
        <geometry>
          <mesh filename="../meshes/stl/BodyYaw_Act1_Link.001.stl" scale="1.0 1.0 1.0"/>
        </geometry>
        <material name="Steel"/>
      </visual>
      <visual name="visual_0_BodyYaw_B11_Link">
        <origin xyz="-0.145 0.03 0.047" rpy="1.571 0 0"/>
        <geometry>
          <mesh filename="../meshes/stl/BodyYaw_B11_Link.001.stl" scale="1.0 1.0 1.0"/>
        </geometry>
        <material name="Steel"/>
      </visual>
      <visual name="visual_0_BodyYaw_B21_Link">
        <origin xyz="-0.145 -0.03 0.047" rpy="1.571 0 0"/>
        <geometry>
          <mesh filename="../meshes/stl/BodyYaw_B21_Link.001.stl" scale="1.0 1.0 1.0"/>
        </geometry>
        <material name="Steel"/>
      </visual>
      <visual name="visual_0_BodyYaw_Link">
        <origin xyz="0 0 0" rpy="0 0 0"/>
        <geometry>
          <mesh filename="../meshes/stl/BodyYaw_Link.001.stl" scale="1.0 1.0 1.0"/>
        </geometry>
        <material name="WhitePlastic"/>
      </visual>
      <visual name="visual_0_Head">
        <origin xyz="-0.048 0 -0.217" rpy="0 0 -1.571"/>
        <geometry>
          <mesh filename="../meshes/stl/Head.001.stl" scale="1.0 1.0 1.0"/>
        </geometry>
        <material name="Steel"/>
      </visual>
      <collision name="collsion_0_BodyYaw_Link.001">
        <origin xyz="0.008 0.002 0.311" rpy="0 0 -1.571"/>
        <geometry>
          <mesh filename="../meshes/stl/BodyYaw_Link.006.stl" scale="1.0 1.0 1.0"/>
        </geometry>
      </collision>
    </link>

    <link name="ARElbow_Link">
      <inertial>
        <origin xyz="0.008 0 0.009" rpy="0 0 0"/>
        <mass value="0.255"/>
        <inertia ixx="0.001" ixy="0" ixz="0" iyy="0.001" iyz="0" izz="0.001"/>
      </inertial>
      <visual name="ARvisual_0_Elbow_Link">
        <origin xyz="0 0 0" rpy="0 0 0"/>
        <geometry>
          <mesh filename="../meshes/stl/ALElbow_Link.002.stl" scale="1.0 1.0 1.0"/>
        </geometry>
        <material name="Steel"/>
      </visual>
    </link>

    <link name="ARShoulder1_Link">
      <inertial>
        <origin xyz="-0.059 0.002 0" rpy="0 0 0"/>
        <mass value="0.474"/>
        <inertia ixx="0.001" ixy="0" ixz="0" iyy="0.001" iyz="0" izz="0.001"/>
      </inertial>
      <visual name="ARvisual_0_Shoulder1_Link">
        <origin xyz="0 0 0" rpy="0 0 0"/>
        <geometry>
          <mesh filename="../meshes/stl/ALShoulder1_Link.002.stl" scale="1.0 1.0 1.0"/>
        </geometry>
        <material name="Steel"/>
      </visual>
    </link>

    <link name="ARShoulder2_Link">
      <inertial>
        <origin xyz="0 0.01 0.002" rpy="0 0 0"/>
        <mass value="0.98"/>
        <inertia ixx="0" ixy="0" ixz="0" iyy="0" iyz="0" izz="0"/>
      </inertial>
      <visual name="ARvisual_0_Shoulder2_Link">
        <origin xyz="0 0 0" rpy="0 0 0"/>
        <geometry>
          <mesh filename="../meshes/stl/ALShoulder2_Link.002.stl" scale="1.0 1.0 1.0"/>
        </geometry>
        <material name="Steel"/>
      </visual>
    </link>

    <link name="ARShoulder3_Link">
      <inertial>
        <origin xyz="0 0 0.19" rpy="0 0 0"/>
        <mass value="1.4"/>
        <inertia ixx="0.001" ixy="0" ixz="0" iyy="0.001" iyz="0" izz="0.001"/>
      </inertial>
      <visual name="ARvisual_0_Shoulder3_Link">
        <origin xyz="0 0 0" rpy="0 0 0"/>
        <geometry>
          <mesh filename="../meshes/stl/ALShoulder3_Link.002.stl" scale="1.0 1.0 1.0"/>
        </geometry>
        <material name="Steel"/>
      </visual>
      <collision name="ARvisual_0_Shoulder3_Link">
        <origin xyz="0 0 0.197" rpy="3.142 0 0"/>
        <geometry>
          <box size="0.078 0.1 0.227"/>
        </geometry>
      </collision>
    </link>

    <link name="ARWristPitch_Link">
      <inertial>
        <origin xyz="0 0 -0.034" rpy="0 0 0"/>
        <mass value="0.788"/>
        <inertia ixx="0.001" ixy="0" ixz="0" iyy="0.001" iyz="0" izz="0.001"/>
      </inertial>
      <visual name="GR_visual_0_Gripper_Root_link">
        <origin xyz="0.005 0 -0.079" rpy="-3.142 0 1.559"/>
        <geometry>
          <mesh filename="../meshes/stl/Gripper_Root_link_Collision.stl" scale="1.0 1.0 1.0"/>
        </geometry>
        <material name="Steel"/>
      </visual>
      <collision name="GR_collision_0_Gripper_Root_link">
        <origin xyz="0.005 0 -0.079" rpy="-3.142 0 1.559"/>
        <geometry>
          <mesh filename="../meshes/stl/Gripper_Root_link_Collision.004.stl" scale="1.0 1.0 1.0"/>
        </geometry>
      </collision>
    </link>

    <link name="ARWristRoll_Link">
      <inertial>
        <origin xyz="0.015 0 0.2" rpy="0 0 0"/>
        <mass value="2.753"/>
        <inertia ixx="0.007" ixy="0" ixz="0" iyy="0.007" iyz="0" izz="0.007"/>
      </inertial>
      <visual name="ARvisual_0_WristRoll_Link">
        <origin xyz="0 0 0" rpy="0 0 0"/>
        <geometry>
          <mesh filename="../meshes/stl/ALWristRoll_Link.002.stl" scale="1.0 1.0 1.0"/>
        </geometry>
        <material name="WhitePlastic"/>
      </visual>
      <visual name="ARvisual_0_Wrist_Act1_Link">
        <origin xyz="-0.036 -0.035 -0.005" rpy="3.076 0.032 0.24"/>
        <geometry>
          <mesh filename="../meshes/stl/ALWrist_Act1_Link.002.stl" scale="1.0 1.0 1.0"/>
        </geometry>
        <material name="Steel"/>
      </visual>
      <visual name="ARvisual_0_Wrist_Act2_Link">
        <origin xyz="-0.036 0.035 -0.005" rpy="-3.07 0.015 0.001"/>
        <geometry>
          <mesh filename="../meshes/stl/ALWrist_Act2_Link.002.stl" scale="1.0 1.0 1.0"/>
        </geometry>
        <material name="Steel"/>
      </visual>
      <visual name="ARvisual_0_Wrist_B11_Link">
        <origin xyz="-0.032 -0.016 0.262" rpy="3.07 0 0"/>
        <geometry>
          <mesh filename="../meshes/stl/ALWrist_B11_Link.002.stl" scale="1.0 1.0 1.0"/>
        </geometry>
        <material name="Steel"/>
      </visual>
      <visual name="ARvisual_0_Wrist_B12_Link">
        <origin xyz="-0.032 -0.016 0.262" rpy="3.07 0.015 -0.001"/>
        <geometry>
          <mesh filename="../meshes/stl/ALWrist_B12_Link.002.stl" scale="1.0 1.0 1.0"/>
        </geometry>
        <material name="Steel"/>
      </visual>
      <visual name="ARvisual_0_Wrist_B21_Link">
        <origin xyz="-0.032 0.016 0.262" rpy="-3.07 0.015 0.001"/>
        <geometry>
          <mesh filename="../meshes/stl/ALWrist_B21_Link.002.stl" scale="1.0 1.0 1.0"/>
        </geometry>
        <material name="Steel"/>
      </visual>
      <visual name="ARvisual_0_Wrist_B22_Link">
        <origin xyz="-0.032 0.016 0.262" rpy="-3.07 0.018 0.001"/>
        <geometry>
          <mesh filename="../meshes/stl/ALWrist_B22_Link.002.stl" scale="1.0 1.0 1.0"/>
        </geometry>
        <material name="Steel"/>
      </visual>
      <collision name="ARvisual_0_WristRoll_Link">
        <origin xyz="0.015 0 0.162" rpy="0 0 -0.012"/>
        <geometry>
          <box size="0.141 0.12 0.308"/>
        </geometry>
      </collision>
    </link>

    <link name="ARWristYaw_Link">
      <inertial>
        <origin xyz="0 0 0" rpy="0 0 0"/>
        <mass value="0.007"/>
        <inertia ixx="0" ixy="0" ixz="0" iyy="0" iyz="0" izz="0"/>
      </inertial>
      <visual name="ARvisual_0_WristYaw_Link">
        <origin xyz="0 0 0" rpy="0 0 0"/>
        <geometry>
          <mesh filename="../meshes/stl/ALWristYaw_Link.002.stl" scale="1.0 1.0 1.0"/>
        </geometry>
        <material name="Steel"/>
      </visual>
    </link>

    <link name="AR_WristFT">
      <inertial>
        <origin xyz="0 0 0" rpy="0 0 0"/>
        <mass value="0.001"/>
        <inertia ixx="0.001" ixy="0" ixz="0" iyy="0.001" iyz="0" izz="0.001"/>
      </inertial>
    </link>

    <joint name="BodyBase_Link" type="fixed">
      <origin xyz="0 0.048 0.217" rpy="0 -3.142 0"/>
      <parent link="RH5_Root_Link"/>
      <child link="BodyBase_Link"/>
      <limit effort="23.0" velocity="1.833"/>
    </joint>

    <joint name="BodyPitch" type="fixed">
      <origin xyz="0 0 0" rpy="3.142 0 1.571"/>
      <parent link="BodyBase_Link"/>
      <child link="BodyPitch_Link"/>
      <axis xyz="0 1.0 0"/>
      <limit lower="-0.367" upper="0.489" effort="140.0" velocity="2.321"/>
    </joint>

    <joint name="BodyRoll" type="fixed">
      <origin xyz="0 0 0" rpy="0 0 0"/>
      <parent link="BodyPitch_Link"/>
      <child link="BodyRoll_Link"/>
      <axis xyz="1.0 0 0"/>
      <limit lower="-0.402" upper="0.402" effort="140.0" velocity="2.321"/>
    </joint>

    <joint name="BodyYaw" type="fixed">
      <origin xyz="0 0 0" rpy="0 0 0"/>
      <parent link="BodyRoll_Link"/>
      <child link="BodyYaw_Link"/>
      <axis xyz="0 0 1.0"/>
      <limit lower="-0.524" upper="0.524" effort="23.0" velocity="1.833"/>
    </joint>

    <joint name="AR_WristFT" type="fixed">
      <origin xyz="0 0 -0.026" rpy="0 0 -1.047"/>
      <parent link="ARWristPitch_Link"/>
      <child link="AR_WristFT"/>
      <limit effort="12.5" velocity="0.1"/>
    </joint>

    <joint name="ARElbow" type="revolute">
      <origin xyz="0 0 0.355" rpy="1.563 -1.571 -0.004"/>
      <parent link="ARShoulder3_Link"/>
      <child link="ARElbow_Link"/>
      <axis xyz="0 0 1.0"/>
      <limit lower="-0.187" upper="1.62" effort="23.0" velocity="1.833"/>
    </joint>

    <joint name="ARShoulder1" type="revolute">
      <origin xyz="0.012 -0.313 0.386" rpy="0 0 -1.328"/>
      <parent link="BodyYaw_Link"/>
      <child link="ARShoulder1_Link"/>
      <axis xyz="1.0 0 0"/>
      <limit lower="-3.054" upper="3.054" effort="135.0" velocity="1.833"/>
    </joint>

    <joint name="ARShoulder2" type="revolute">
      <origin xyz="0 0 0" rpy="0 -3.142 0"/>
      <parent link="ARShoulder1_Link"/>
      <child link="ARShoulder2_Link"/>
      <axis xyz="0 1.0 0"/>
      <limit lower="-1.571" upper="0.524" effort="167.0" velocity="1.833"/>
    </joint>

    <joint name="ARShoulder3" type="revolute">
      <origin xyz="0 0 0" rpy="0 0 3.141"/>
      <parent link="ARShoulder2_Link"/>
      <child link="ARShoulder3_Link"/>
      <axis xyz="0 0 1.0"/>
      <limit lower="-3.054" upper="3.054" effort="135.0" velocity="1.833"/>
    </joint>

    <joint name="ARWristPitch" type="revolute">
      <origin xyz="0 0 0" rpy="0 0 0"/>
      <parent link="ARWristYaw_Link"/>
      <child link="ARWristPitch_Link"/>
      <axis xyz="0 1.0 0"/>
      <limit lower="-3.142" upper="3.142" effort="12.5" velocity="0.1"/>
    </joint>

    <joint name="ARWristRoll" type="revolute">
      <origin xyz="0.386 0 0" rpy="1.571 0 -1.571"/>
      <parent link="ARElbow_Link"/>
      <child link="ARWristRoll_Link"/>
      <axis xyz="0 0 -1.0"/>
      <limit lower="-175.0" upper="175.0" effort="18.0" velocity="1.833"/>
    </joint>

    <joint name="ARWristYaw" type="revolute">
      <origin xyz="0 0 0" rpy="0 0 0"/>
      <parent link="ARWristRoll_Link"/>
      <child link="ARWristYaw_Link"/>
      <axis xyz="1.0 0 0"/>
      <limit lower="-0.785" upper="1.257" effort="12.5" velocity="0.1"/>
    </joint>

    <material name="Steel">
      <color rgba="0.249 0.249 0.249 1.0"/>
    </material>

    <material name="WhitePlastic">
      <color rgba="0.924 0.907 1.0 1.0"/>
    </material>

  </robot>
